Workbook

Sheet Observações
B1: #VALUE!
B2: Data | C2: Observações
C3: Objetivos:
C5: Lesões mais graves:
C6: Avaliações:
C8: Treino atual
C11: Disponibilidade de treinos

Sheet Pivot
A1: GRUPO MUSCULAR | B1: TRÍCEPS
A3: Rótulos de Linha
A4: FLEXÃO BRAÇOS FECHADA
A5: TRÍCEPS COICE UNILATERAL
A6: TRÍCEPS FRANCÊS DUMBBELL
A7: TRÍCEPS FRANCÊS POLIA CORDA
A8: TRÍCEPS FRANCÊS POLIA UNILATERAL
A9: TRÍCEPS FRANCÊS UNILATERAL
A10: TRÍCEPS POLIA BARRA RETA
A11: TRÍCEPS POLIA BARRA RETA INVERTIDO
A12: TRÍCEPS POLIA CORDA
A13: TRÍCEPS POLIA UNILATERAL
A14: TRÍCEPS TESTA BARRA "H"
... A20: Total Geral

Sheet Uso interno
A1: GRUPO MUSCULAR | C1: ABS | D1: ADUTOR | E1: BÍCEPS | F1: COSTAS | G1: FUNCIONAL | H1: GÊMEOS | I1: GLÚTEO_MÁXIMO | J1: GLÚTEO_MÉDIO | K1: ISQUIOSSURAIS | L1: LOMBAR | M1: OMBRO | N1: PEITORAL | O1: QUADRÍCEPS | P1: TIBIAL | Q1: TRAPÉZIO | R1: TRÍCEPS
A2: FUNÇÃO UNIQUE | C2: ABDOMINAL MÃO ESPALDAR | D2: ADUÇÃO CANELEIRA SOLO | E2: ROSCA "T" POLIA | F2: BARRA FIXA ABERTA | G2: BURPEE | H2: GÊMEOS EM PÉ STEP | I2: AFUNDO CAIXOTE | J2: ABDUÇÃO CANELEIRA SOLO | K2: CADEIRA FLEXORA | L2: EXTENSAO TRONCO BANCO DORSAL | M2: CRUCIFIXO INVERTIDO CURVADO DUMBELL | N2: CROSS OVER CURV POLIA ALTA | O2: AFUNDO BARRA | P2: TIBIAL POLIA | Q2: ADUÇÃO ESCAPULAR POLIA CORDA | R2: FLEXÃO BRAÇOS FECHADA
A3: GOOGLE PLANILHAS | C3: ABDOMINAL MÁQUINA | D3: ADUÇÃO POLIA | E3: ROSCA ALTERNADA | F3: PULL DOWN BARRA ABERTA | G3: CORDA NAVAL | H3: GÊMEOS EM PÉ UNI | I3: AFUNDO REVERSO SMITH STEP PÉS FRENTE | J3: ABDUÇÃO EM PÉ MINI BAND | K3: CADEIRA FLEXORA UNIPODAL | M3: CRUCIFIXO INVERTIDO CURVADO POLIA | N3: CROSS OVER POLIA MÉDIA | O3: AFUNDO SMITH | Q3: ELEVAÇÃO Y | R3: TRÍCEPS COICE UNILATERAL
C4: ABDOMINAL POLIA CORDA | D4: CADEIRA ADUTORA | E4: ROSCA CONCENTRADO | F4: PUXADA ARTICULADA | G4: EQUILÍBRIO DISCO | H4: GÊMEOS LEG PRESS 45° | I4: AGACHAMENTO BÚLGARO BANCO | J4: ABDUÇÃO MINI BAND SOLO | K4: FLEXÃO JOELHO BOLA | M4: CRUCIFIXO INVERTIDO MÁQUINA | N4: CRUCIFIXO CURVADO POLIA | O4: AGACHAMENTO FRONTAL 1 DUMBELL | Q4: ENCOLHIMENTO OMBRO POLIA | R4: TRÍCEPS FRANCÊS DUMBBELL
C5: ABDOMINAL RODINHA | D5: CADEIRA ADUTORA 45 | E5: ROSCA DIRETA | F5: PUXADA GRAVITON ABERTA | G5: EQUILÍBRIO DISCO UNIPODAL | H5: GÊMEOS SENTADO MÁQUINA | I5: AGACHAMENTO BÚLGARO SMITH | J5: ABDUÇÃO POLIA | K5: FLEXÃO NORDICA | M5: CRUCIFIXO INVERTIDO POLIA | N5: CRUCIFIXO INCLINADO DUMBELL | O5: AGACHAMENTO FRONTAL BARRA | Q5: ROTAÇÃO OMBRO MINI BAND | R5: TRÍCEPS FRANCÊS POLIA CORDA
C6: ABDOMINAL SOLO | E6: ROSCA DIRETA BARRA "W" | F6: PUXADA GRAVITON FECHADA | G6: ESCALADOR | I6: COICE POLIA UNILATERAL | J6: CADEIRA ABDUTORA | K6: FLEXÃO NORDICA INVERTIDA | M6: DESENVOLVIMENTO ARNOLD | N6: CRUCIFIXO INCLINADO POLIA | O6: AGACHAMENTO HACK | R6: TRÍCEPS FRANCÊS POLIA UNILATERAL
C7: PERDIGUEIRO DINÂMICO | E7: ROSCA DIRETA DUMBBELL | F7: PUXADA MÁQUINA | I7: ELEVAÇÃO PÉLVICA SOLAS UNIDAS | J7: CADEIRA ABDUTORA 45 | K7: FLEXORA EM PÉ ARTICULADA | M7: DESENVOLVIMENTO BARRA | N7: CRUCIFIXO MÁQUINA | O7: AGACHAMENTO LIVRE BARRA | R7: TRÍCEPS FRANCÊS UNILATERAL
C8: PERDIGUEIRO ESTÁTICO | E8: ROSCA DIRETA DUMBBELL BANCO 45 | F8: PUXADA POLIA CORDA | I8: ELEVAÇÃO QUADRIL BOLA | J8: OSTRA | K8: MESA FLEXORA | M8: DESENVOLVIMENTO DUMBBELL | N8: CRUCIFIXO POLIA ALTA | O8: AGACHAMENTO LIVRE PESO CORPORAL | R8: TRÍCEPS POLIA BARRA RETA
C9: PRANCHA VENTRAL | E9: ROSCA DIRETA INVERTIDA | F9: PUXADA PULLEY ABERTA MAPFIT | I9: ELEVAÇÃO QUADRIL COSTAS BANCO | J9: PASSADA LATERAL ALTERNADO MINI BAND | K9: MESA FLEXORA UNIPODAL | M9: DESENVOLVIMENTO DUMBBELL FECHADO | N9: CRUCIFIXO POLIA MÉDIA | O9: AGACHAMENTO NEUTRO DUMBELL | R9: TRÍCEPS POLIA BARRA RETA INVERTIDO
E10: ROSCA DIRETA POLIA BARRA RETA | F10: PUXADA PULLEY ABERTA PUXADORES | I10: ELEVAÇÃO QUADRIL COSTAS BANCO UNI | J10: PASSADA LATERAL MINI BAND | K10: STIFF BARRA | M10: ELEVAÇÃO FRONTAL BARRA | N10: CRUCIFIXO RETO DUMBELL | O10: AGACHAMENTO PC ISOMÉTRICO | R10: TRÍCEPS POLIA CORDA
E11: ROSCA DIRETA POLIA CÓCORAS | F11: PUXADA PULLEY ALTERNADA ABERTA | I11: ELEVAÇÃO QUADRIL SOLO | K11: STIFF DUMBELL | M11: ELEVAÇÃO FRONTAL DUMBELL | N11: CRUCIFIXO RETO POLIA | O11: AGACHAMENTO SMITH | R11: TRÍCEPS POLIA UNILATERAL
E12: ROSCA DIRETA POLIA CORDA | F12: PUXADA PULLEY ALTERNADA FECHADA | I12: ELEVAÇÃO QUADRIL SOLO UNIPODAL | K12: STIFF DUMBELL UNIPODAL | M12: ELEVAÇÃO FRONTAL DUMBELL NEUTRA | N12: CRUCIFIXO SENTADO POLIA | O12: AGACHAMENTO SUMO BARRA | R12: TRÍCEPS TESTA BARRA "H"
E13: ROSCA DIRETA POLIA UNILATERAL | F13: PUXADA PULLEY BARRA "U" | I13: EXTENSAO QUADRIL BANCO DORSAL | M13: ELEVAÇÃO FRONTAL POLIA BARRA | N13: FLEXÃO DE BRAÇOS | O13: AGACHAMENTO SUMO DUMBELL | R13: TRICEPS TESTA BARRA RETA
E14: ROSCA DIRETA TRX | F14: PUXADA PULLEY BARRA ABERTA | I14: EXTENSÃO QUADRIL MINI BAND | M14: ELEVAÇÃO FRONTAL UNI DUMBELL | N14: FLEXÃO DE BRAÇOS APOIO JOELHOS | O14: AGACHAMENTO TRX | R14: TRÍCEPS TESTA POLIA BARRA RETA
E15: ROSCA MARTELO BARRA "H" | F15: PUXADA PULLEY FECHADA MAPFIT SUPINADA | I15: GLÚTEO 4 APOIOS CANELEIRA | M15: ELEVAÇÃO LATERAL | N15: SUPINO INCLINADO BARRA | O15: AVANÇO BARRA | R15: TRÍCEPS TESTA POLIA CORDA
E16: ROSCA MARTELO DUMBBELL | F16: PUXADA PULLEY FRENTE ROMANA | I16: GLÚTEO EM PÉ POLIA ESTENDIDO | M16: ELEVAÇÃO LATERAL 45 | N16: SUPINO INCLINADO DUMBELL | O16: AVANÇO PESO CORPORAL | R16: TRÍCEPS TESTA POLIA UNILATERAL
E17: ROSCA SCOTT | F17: PUXADA PULLEY FRENTE SUPINADA | I17: GLÚTEO EM PÉ POLIA FLEXIONADO | M17: ELEVAÇÃO LATERAL UNI POLIA | N17: SUPINO INCLINADO MÁQUNA | O17: CADEIRA EXTENSORA | R17: TRÍCEPS TESTA TRX
E18: ROSCA UNILATERAL POLIA ALTA | F18: PUXADA PULLEY FRENTE TRIÂNGULO | I18: LEVANTAMENTO TERRA BARRA | M18: ELEVAÇÃO LATERAL UNILATERAL | N18: SUPINO RETO BARRA | O18: CADEIRA EXTENSORA UNIPODAL
F19: PUXADA PULLEY MÉDIA MAPFIT | I19: LEVANTAMENTO TERRA SUMO | M19: ELEVAÇÃO UNILATERAL DUMBELL BANCO INCL | N19: SUPINO RETO DUMBELL | O19: EXTENSÃO DE JOELHOS CANELEIRA SOLO
F20: PUXADA PULLEY PUXADORES SUPINAD | I20: MEIO LEVANTAMENTO TERRA BARRA | M20: MANGUITO ROTAÇÃO EXTERNA | N20: SUPINO RETO MÁQUINA | O20: FLEXÃO DE QUADRIL UNI SOLO
F21: PUXADA PULLEY SUPINADA MAPFIT | I21: SUBIDA CAIXOTE | M21: MANGUITO ROTAÇÃO INTERNA | N21: SUPINO SENTADO POLIA | O21: LEG PRESS 45° ABERTO
F22: REMADA ARTICULADA ANILHA ABERT | M22: REMADA ALTA POLIA BARRA | N22: SUPINO TRX | O22: LEG PRESS 45° PÉS FECHADO
F23: REMADA ARTICULADA ANILHA FECH | M23: REMADA ALTA POLIA TRIÂNGULO | O23: LEG PRESS 45° UNIPODAL
F24: REMADA BAIXA ABERTA PRONADA | O24: LEG PRESS HORIZ FECHADO
F25: REMADA BAIXA ABERTA SUPINADA | O25: LEG PRESS HORIZONTAL
F26: REMADA BAIXA BARRA ROMANA | O26: LEG PRESS HORIZONTAL UNIPODAL
F27: REMADA BAIXA BARRA"U" | O27: PASSADA DUMBELL
F28: REMADA BAIXA MAPFIT
F29: REMADA BAIXA SUPINADA MAPFIT
F30: REMADA BAIXA TRIÂNGULO
F31: REMADA CAVALINHO
F32: REMADA CURV DUMBELL
F33: REMADA CURV POLIA TRIÂNGULO
F34: REMADA CURVADA BARRA
F35: REMADA MEADOWS ROW
F36: REMADA PRANCHA V 3 APOIOS DUMBELL
F37: REMADA TRX ABERTA
F38: REMADA TRX ABERTA+FECHADA
F39: REMADA TRX FECHADA
F40: REMADA UNILATERAL DUMBELL
...

Sheet Tabelas %G
B1: #VALUE!
B2: % de gordura para crianças e adolescentes (7 a 17 anos de idade) | F2: % de gordura para Mulheres
C3: Meninos | D3: Meninas | F3: Nível /Idade | G3: 18 - 25 | H3: 26 - 35 | I3: 36 - 45 | J3: 46 - 55 | K3: 56 - 65
B4: Excessivamente Baixa | C4: Até 6 | D4: Até 12 | F4: Excelente | G4: 13 a 16 | H4: 14 a 16 | I4: 16 a 19 | J4: 17 a 21 | K4: 18 a 22
B5: Baixa | C5: 6 a 10 | D5: 12 a 15 | F5: Bom | G5: 17 a 19 | H5: 18 a 20 | I5: 20 a 23 | J5: 23 a 25 | K5: 24 a 26
B6: Adequada | C6: 10 a 20 | D6: 15 a 25 | F6: Abaixo da Média | G6: 20 a 22 | H6: 21 a 23 | I6: 24 a 26 | J6: 26 a 28 | K6: 27 a 29
B7: Moderadamente Alta | C7: 20 a 25 | D7: 25 a 30 | F7: Média | G7: 23 a 25 | H7: 24 a 25 | I7: 27 a 29 | J7: 29 a 31 | K7: 30 a 32
B8: Alta | C8: 25 a 31 | D8: 30 a 36 | F8: Acima da Média | G8: 26 a 28 | H8: 27 a 29 | I8: 30 a 32 | J8: 32 a 34 | K8: 33 a 35
B9: Excessivamente Alta | C9: Acima de 31 | D9: Acima de 36 | F9: Ruim | G9: 29 a 31 | H9: 31 a 33 | I9: 33 a 36 | J9: 35 a 38 | K9: 36 a 38
B10: Fonte: Lohman, 1987 | F10: Muito Ruim | G10: 33 a 43 | H10: 36 a 49 | I10: 38 a 48 | J10: 39 a 50 | K10: 39 a 49
F11: Fonte: Pollock & Wilmore, 1993
F13: % de gordura para Homens
F14: Nível /Idade | G14: 18 - 25 | H14: 26 - 35 | I14: 36 - 45 | J14: 46 - 55 | K14: 56 - 65
F15: Excelente | G15: 4 a 6 | H15: 8 a 11 | I15: 10 a 14 | J15: 12 a 16 | K15: 13 a 18
F16: Bom | G16: 8 a 10 | H16: 12 a 15 | I16: 16 a 18 | J16: 18 a 20 | K16: 20 a 21
F17: Abaixo da Média | G17: 12 a 13 | H17: 16 a 18 | I17: 19 a 21 | J17: 21 a 23 | K17: 22 a 23
F18: Média | G18: 14 a 16 | H18: 18 a 20 | I18: 21 a 23 | J18: 24 a 25 | K18: 24 a 25
F19: Acima da Média | G19: 17 a 20 | H19: 22 a 24 | I19: 24 a 25 | J19: 26 a 27 | K19: 26 a 27
F20: Ruim | G20: 20 a 24 | H20: 24 a 27 | I20: 27 a 29 | J20: 28 a 30 | K20: 28 a 30
F21: Muito Ruim | G21: 26 a 36 | H21: 28 a 36 | I21: 30 a 39 | J21: 32 a 38 | K21: 32 a 38
F22: Fonte: Pollock & Wilmore, 1993

Sheet Rotina
B1: #VALUE!
B2: Horário | C2: Segunda | D2: Terça | E2: Quarta | F2: Quinta | G2: Sexta | H2: Sábado | I2: Domingo
B3: 0.25
B4: 0.29166667
B5: 0.33333333
B6: 0.375
B7: 0.41666667
B8: 0.45833333
B9: 0.5
B10: 0.54166667
B11: 0.58333333
B12: 0.625
B13: 0.66666667
B14: 0.70833333
... B19: 0.91666667

Sheet Menu
H2: MASCULINO
H3: FEMININO
B15: ALUNO: | E15: Gabriel
B16: SEXO: | E16: MASCULINO
B17: PESO (kg): | E17: 88
B18: ALTURA (m): | E18: 1.87
B19: IMC (kg/m²): | E19: =IFERROR(IF(E17/E18^2=0, "", E17/E18^2), "") -> 25.165146 | F19: =IFERROR(IF(F17/$C$11^2=0, "", F17/$C$11^2), "") | G19: =IFERROR(IF(G17/$C$11^2=0, "", G17/$C$11^2), "") | H19: =IFERROR(IF(H17/$C$11^2=0, "", H17/$C$11^2), "") | I19: =IFERROR(IF(I17/$C$11^2=0, "", I17/$C$11^2), "") | J19: =IFERROR(IF(J17/$C$11^2=0, "", J17/$C$11^2), "") | K19: =IFERROR(IF(K17/$C$11^2=0, "", K17/$C$11^2), "") | L19: =IFERROR(IF(L17/$C$11^2=0, "", L17/$C$11^2), "") | M19: =IFERROR(IF(M17/$C$11^2=0, "", M17/$C$11^2), "")
B20: DATA DE NASCIMENTO: | E20: 35146
B21: DATA DA AVALIAÇÃO:
B26: Informações Sobre Tempo Contrato
B28: Plano adiquirido: | E28: 3
B29: Data de Inicio: | E29: 45828
B30: Data do Fim: | E30: 45832 | G30: Dias p/ Fim do Ciclo: | J30: =E30-E29&" Dias para o vencimento" -> 4 Dias para o vencimento
B31: Valor: | G31: Meio de pagamento: | J31: =IFERROR(IF(M26/$C$11^2=0, "", M26/$C$11^2), "")
B33: Informações Sobre o Aluno
B34: Dores e Intensidade:
B35: Principais objetivo:
B36: Principais Limitação:
B37: Referencia de Objetivo: | F37: =IFERROR(IF(F31/$C$11^2=0, "", F31/$C$11^2), "") | G37: =IFERROR(IF(G31/$C$11^2=0, "", G31/$C$11^2), "") | H37: =IFERROR(IF(H31/$C$11^2=0, "", H31/$C$11^2), "") | I37: =IFERROR(IF(I31/$C$11^2=0, "", I31/$C$11^2), "") | J37: =IFERROR(IF(K31/$C$11^2=0, "", K31/$C$11^2), "") | K37: =IFERROR(IF(#REF!/$C$11^2=0, "",#REF!/ $C$11^2), "") | L37: =IFERROR(IF(L31/$C$11^2=0, "", L31/$C$11^2), "") | M37: =IFERROR(IF(J31/$C$11^2=0, "", J31/$C$11^2), "")
B38: Pontos fracos:
B39: Pontos fortes:
B40: Exercicios Proibidos:
B42: Metodos Utilizados:
C44: METODOS: | E44: Data: | F44: Data: | G44: Data: | H44: Data: | I44: Observações: | K44: Peso: | L44: % de Gordura e/ou Resultados
B45: REPETIÇÕES FORÇADAS ou ROUBADA
B46: "DROP-SET" OU REGRESSIVO ou EXAUSTÃO
B47: EXCÊNTRICO ou NEGATIVO
B48: CONCENTRADO
B49: INSISTÊNCIA ou BOMBEADA
B50: DIVISÃO DOS MOVIMENTOS
B51: SUSTENTAÇÃO ou ISOMÉTRICO
B52: TEMPO SOB TENSÃO ("TRAINING TO FAILURE")
B53: PIRÂMIDE CRESCENTE
B54: PIRÂMIDE DECRESCENTE
B55: PIRÂMIDE TRUNCADA
B56: SUPER-SÉRIES (BI, TRI, POLI SET) ou CIRCUITOS
... B74: "REST-PAUSE STRENGTH" ("CLUSTER SERIES")

Sheet Avaliação Presencial
C2: AVALIAÇÃO PRESENCIAL
F3: ALUNO: | G3: =Menu!E15 -> Gabriel
F4: SEXO: | G4: =Menu!E16 -> MASCULINO
F5: DATA DE NASCIMENTO: | G5: =Menu!E20 -> 35146
G10: SEÇÃO DE ANÁLISE
G11: DATA: | H11: 45787 | I11: 45796 | J11: 46165
G12: INTERVALO ENTRE AS AVALICOES: | H12: =IF((I11-H11)>0, (I11-H11),"") -> 9 | I12: =IF((J11-I11)>0, (J11-I11),"") -> 369 | J12: =IF((K11-J11)>0, (K11-J11),"") | K12: =IF((L11-K11)>0, (L11-K11),"") | L12: =IF((M11-L11)>0, (M11-L11),"") | M12: =IF((N11-M11)>0, (N11-M11),"") | N12: =IF((O11-N11)>0, (O11-N11),"") | O12: =IF((P11-O11)>0, (P11-O11),"") | ... Q12: =IF((R11-Q11)>0, (R11-Q11),"")
G13: IDADE: | H13: =INT(H11-G5)/365 -> 29.153425 | I13: =INT(I11-G5)/365 -> 29.178082 | J13: =INT(J11-G5)/365 -> 30.189041 | K13: =INT(K11-G5)/365 -> -96.290411 | L13: =INT(L11-G5)/365 -> -96.290411 | M13: =INT(M11-G5)/365 -> -96.290411 | N13: =INT(N11-G5)/365 -> -96.290411 | O13: =INT(O11-G5)/365 -> -96.290411 | P13: =INT(P11-G5)/365 -> -96.290411 | Q13: =INT(Q11-G5)/365 -> -96.290411
G14: HORARIO: | H14: 0.87708333
G15: CIRCUNFERENCIA | H15: AV1 | I15: AV2 | J15: AV3 | K15: AV4 | L15: AV5 | M15: AV6 | N15: AV7 | O15: AV8 | P15: AV9 | Q15: AV10
G16: Pescoco
G17: Ombros
G18: Tórax Expirando
G19: Tórax Inspirando
G20: Braço direito Relaxado | H20: 38
G21: Braço direito Contraido
G22: Braço esquerdo Relaxado
G23: Braço esquerdo Contraido
G24: Abdominal | H24: 94
G25: Cintura | H25: 80
G26: Quadril | H26: 95
G27: Coxa Direita Proximal (Dobra Glutea)
G28: Coxa Direita Medial (20 cm do bordo superior da patela) | H28: 60.5
G29: Coxa Direita Distal
G30: Coxa Esquerda Proximal (Dobra Glutea)
G31: Coxa Esquerda Medial (20 cm do bordo superior da patela)
G32: Coxa Esquerda Distal
G33: Panturrilha direita
G34: Panturrilha esquerda
G35: DOBRAS CUTANEAS
G36: Medida 1 [mm]: Peitoral
G37: Medida 2 [mm]: Axilar média
G38: Medida 3 [mm]: Subescapular
G39: Medida 4 [mm]: Tricipital | H39: 11
G40: Medida 5 [mm]: Bicipital
G41: Medida 6 [mm]: Suprailíaca
G42: Medida 7 [mm]: Abdominal | H42: 30
G43: Medida 8 [mm]: Coxa | H43: 25
G44: Medida 9 [mm]: Panturrilha medial
G45: Soma das 9 medidas [mm] | H45: =SUM(H36:H44) -> 66 | I45: =SUM(I36:I44) -> 0 | J45: =SUM(J36:J44) -> 0 | K45: =SUM(K36:K44) -> 0 | L45: =SUM(L36:L44) -> 0 | M45: =SUM(M36:M44) -> 0 | N45: =SUM(N36:N44) -> 0 | O45: =SUM(O36:O44) -> 0 | ... Q45: =SUM(Q36:Q44) -> 0
...

Sheet Avaliação Online
B2: AVALIAÇÃO ONLINE | F2: ALUNO: | G2: =Menu!E15 -> Gabriel | N2: COMO MEDIR → | O2: Braço
O3: Ombro-a-ombro
O4: Tórax
O5: Coxa
O6: Panturrilha
O7: Abdominal, Cintura e Quadril
B10: DATA ----------> | C10: 45542 | D10: =C10+15 -> 45557 | E10: =D10+15 -> 45572 | F10: =E10+15 -> 45587 | G10: =F10+15 -> 45602 | H10: =G10+15 -> 45617 | I10: =H10+15 -> 45632 | J10: =I10+15 -> 45647 | K10: =J10+15 -> 45662 | L10: =K10+15 -> 45677 | N10: AVALIAÇÃO COMPARAÇÃO
B11: PARTE DO CORPO | C11: AV1 | D11: AV2 | E11: AV3 | F11: AV4 | G11: AV5 | H11: AV6 | I11: AV7 | J11: AV8 | K11: AV9 | L11: AV10 | N11: DATA AVALIAÇÃO
B12: Braço direito Relaxado | N12: ANÁLISE DOS DADOS
B13: Braco Direito Contraio
B14: Braço esquerdo Relaxado | N14: Peso
B15: Braco Esquerdo Contraio
B16: Ombro | N16: % gordura
B17: Tórax | N17: ¼
B18: Abdominal | N18: Massa gorda
B19: Cintura
B20: Quadril
B21: Coxa direita DISTAL
B22: Coxa esquerda DISTAL
B23: Panturrilha direita
B24: Panturrilha esquerda

Sheet Nivel de treinamento
A36: CALCULADORA
B37: Iniciante (1 ponto) | C37: Intermediário (2 pontos) | D37: Avançado (3 pontos) | E37: Ext. avançado (4 pontos)
A38: Tempo de treino sem interupção | E38: 4
A39: Destreino | E39: 4
A40: Experiência prévia | E40: 4
A41: Técnica | E41: 4
A42: Valores de força | E42: 4
A43: Total | E43: =SUM(B38:E42) -> 20
A44: Média | E44: =AVERAGE(B38:E42) -> 4
A46: REFERÊNCIA:
A47: SANTOS JUNIOR, E. R. T. ; SALLES, B. F. ; DIAS, I. ; RIBEIRO, A. S. ; SIMÃO, R. . Classification and Determination Model of Resistance Training Status. STRENGTH AND CONDITIONING JOURNAL, 2021.

Sheet Teste ANAEROBIA
C1: NÃO MEXER ->
C13: PARTE ANAERÓBIA | M13: PARTE ANAERÓBIA
C14: Teste de resistência de carga/ 1RM SUPERIORES | M14: Teste de resistência de carga/ 1RM INFERIORES
C15: Data do teste | D15: Exercício | E15: Nº de repetições (entre 1 e 15) | F15: Carga (kg) | G15: Link do exercício | H15: %1RM CORRESPONDENTE | I15: CARGA*100/%1RM | J15: 1RM referente ao exercício feito | M15: Data do teste | N15: Exercício | O15: Nº de repetições (entre 1 e 15) | P15: Carga (kg) | Q15: Link do exercício | R15: %1RM CORRESPONDENTE | S15: CARGA*100/%1RM | T15: 1RM referente ao exercício feito
D16: Supino reto | E16: 12 | F16: 120 | H16: =IFERROR(VLOOKUP(Tabela728[[#This Row],[Nº de repetições (entre 1 e 15)]],'[1]Teste Físico'!$T$50:$U$65,2,0),"-") -> 67 | I16: =IFERROR(Tabela728[[#This Row],[Carga (kg)]]*100/Tabela728[[#This Row],[%1RM CORRESPONDENTE]],"-") -> 179.10448 | J16: =IFERROR(Tabela728[[#This Row],[CARGA*100/%1RM]]-2.5*(Tabela728[[#This Row],[CARGA*100/%1RM]])*(100-Tabela728[[#This Row],[%1RM CORRESPONDENTE]])/1000,"-") -> 164.32836 | N16: Cadeira flexora | O16: 12 | P16: 120 | R16: =IFERROR(VLOOKUP(Tabela72833[[#This Row],[Nº de repetições (entre 1 e 15)]],'[1]Teste Físico'!$T$50:$U$65,2,0),"-") -> 67 | S16: =IFERROR(Tabela72833[[#This Row],[Carga (kg)]]*100/Tabela72833[[#This Row],[%1RM CORRESPONDENTE]],"-") -> 179.10448 | T16: =IFERROR(Tabela72833[[#This Row],[CARGA*100/%1RM]]-2.5*(Tabela72833[[#This Row],[CARGA*100/%1RM]])*(100-Tabela72833[[#This Row],[%1RM CORRESPONDENTE]])/1000,"-") -> 164.32836
D17: Puxada frontal | E17: 10 | F17: 120 | H17: =IFERROR(VLOOKUP(Tabela728[[#This Row],[Nº de repetições (entre 1 e 15)]],'[1]Teste Físico'!$T$50:$U$65,2,0),"-") -> 75 | I17: =IFERROR(Tabela728[[#This Row],[Carga (kg)]]*100/Tabela728[[#This Row],[%1RM CORRESPONDENTE]],"-") -> 160 | J17: =IFERROR(Tabela728[[#This Row],[CARGA*100/%1RM]]-2.5*(Tabela728[[#This Row],[CARGA*100/%1RM]])*(100-Tabela728[[#This Row],[%1RM CORRESPONDENTE]])/1000,"-") -> 150 | R17: =IFERROR(VLOOKUP(Tabela72833[[#This Row],[Nº de repetições (entre 1 e 15)]],'[1]Teste Físico'!$T$50:$U$65,2,0),"-") -> - | S17: =IFERROR(Tabela72833[[#This Row],[Carga (kg)]]*100/Tabela72833[[#This Row],[%1RM CORRESPONDENTE]],"-") -> - | T17: =IFERROR(Tabela72833[[#This Row],[CARGA*100/%1RM]]-2.5*(Tabela72833[[#This Row],[CARGA*100/%1RM]])*(100-Tabela72833[[#This Row],[%1RM CORRESPONDENTE]])/1000,"-") -> -
D18: Supino reto | H18: =IFERROR(VLOOKUP(Tabela728[[#This Row],[Nº de repetições (entre 1 e 15)]],'[1]Teste Físico'!$T$50:$U$65,2,0),"-") -> - | I18: =IFERROR(Tabela728[[#This Row],[Carga (kg)]]*100/Tabela728[[#This Row],[%1RM CORRESPONDENTE]],"-") -> - | J18: =IFERROR(Tabela728[[#This Row],[CARGA*100/%1RM]]-2.5*(Tabela728[[#This Row],[CARGA*100/%1RM]])*(100-Tabela728[[#This Row],[%1RM CORRESPONDENTE]])/1000,"-") -> - | R18: =IFERROR(VLOOKUP(Tabela72833[[#This Row],[Nº de repetições (entre 1 e 15)]],'[1]Teste Físico'!$T$50:$U$65,2,0),"-") -> - | S18: =IFERROR(Tabela72833[[#This Row],[Carga (kg)]]*100/Tabela72833[[#This Row],[%1RM CORRESPONDENTE]],"-") -> - | T18: =IFERROR(Tabela72833[[#This Row],[CARGA*100/%1RM]]-2.5*(Tabela72833[[#This Row],[CARGA*100/%1RM]])*(100-Tabela72833[[#This Row],[%1RM CORRESPONDENTE]])/1000,"-") -> -
H19: =IFERROR(VLOOKUP(Tabela728[[#This Row],[Nº de repetições (entre 1 e 15)]],'[1]Teste Físico'!$T$50:$U$65,2,0),"-") -> - | I19: =IFERROR(Tabela728[[#This Row],[Carga (kg)]]*100/Tabela728[[#This Row],[%1RM CORRESPONDENTE]],"-") -> - | J19: =IFERROR(Tabela728[[#This Row],[CARGA*100/%1RM]]-2.5*(Tabela728[[#This Row],[CARGA*100/%1RM]])*(100-Tabela728[[#This Row],[%1RM CORRESPONDENTE]])/1000,"-") -> - | R19: =IFERROR(VLOOKUP(Tabela72833[[#This Row],[Nº de repetições (entre 1 e 15)]],'[1]Teste Físico'!$T$50:$U$65,2,0),"-") -> - | S19: =IFERROR(Tabela72833[[#This Row],[Carga (kg)]]*100/Tabela72833[[#This Row],[%1RM CORRESPONDENTE]],"-") -> - | T19: =IFERROR(Tabela72833[[#This Row],[CARGA*100/%1RM]]-2.5*(Tabela72833[[#This Row],[CARGA*100/%1RM]])*(100-Tabela72833[[#This Row],[%1RM CORRESPONDENTE]])/1000,"-") -> -
H20: =IFERROR(VLOOKUP(Tabela728[[#This Row],[Nº de repetições (entre 1 e 15)]],'[1]Teste Físico'!$T$50:$U$65,2,0),"-") -> - | I20: =IFERROR(Tabela728[[#This Row],[Carga (kg)]]*100/Tabela728[[#This Row],[%1RM CORRESPONDENTE]],"-") -> - | J20: =IFERROR(Tabela728[[#This Row],[CARGA*100/%1RM]]-2.5*(Tabela728[[#This Row],[CARGA*100/%1RM]])*(100-Tabela728[[#This Row],[%1RM CORRESPONDENTE]])/1000,"-") -> - | R20: =IFERROR(VLOOKUP(Tabela72833[[#This Row],[Nº de repetições (entre 1 e 15)]],'[1]Teste Físico'!$T$50:$U$65,2,0),"-") -> - | S20: =IFERROR(Tabela72833[[#This Row],[Carga (kg)]]*100/Tabela72833[[#This Row],[%1RM CORRESPONDENTE]],"-") -> - | T20: =IFERROR(Tabela72833[[#This Row],[CARGA*100/%1RM]]-2.5*(Tabela72833[[#This Row],[CARGA*100/%1RM]])*(100-Tabela72833[[#This Row],[%1RM CORRESPONDENTE]])/1000,"-") -> -
H21: =IFERROR(VLOOKUP(Tabela728[[#This Row],[Nº de repetições (entre 1 e 15)]],'[1]Teste Físico'!$T$50:$U$65,2,0),"-") -> - | I21: =IFERROR(Tabela728[[#This Row],[Carga (kg)]]*100/Tabela728[[#This Row],[%1RM CORRESPONDENTE]],"-") -> - | J21: =IFERROR(Tabela728[[#This Row],[CARGA*100/%1RM]]-2.5*(Tabela728[[#This Row],[CARGA*100/%1RM]])*(100-Tabela728[[#This Row],[%1RM CORRESPONDENTE]])/1000,"-") -> - | R21: =IFERROR(VLOOKUP(Tabela72833[[#This Row],[Nº de repetições (entre 1 e 15)]],'[1]Teste Físico'!$T$50:$U$65,2,0),"-") -> - | S21: =IFERROR(Tabela72833[[#This Row],[Carga (kg)]]*100/Tabela72833[[#This Row],[%1RM CORRESPONDENTE]],"-") -> - | T21: =IFERROR(Tabela72833[[#This Row],[CARGA*100/%1RM]]-2.5*(Tabela72833[[#This Row],[CARGA*100/%1RM]])*(100-Tabela72833[[#This Row],[%1RM CORRESPONDENTE]])/1000,"-") -> -
H22: =IFERROR(VLOOKUP(Tabela728[[#This Row],[Nº de repetições (entre 1 e 15)]],'[1]Teste Físico'!$T$50:$U$65,2,0),"-") -> - | I22: =IFERROR(Tabela728[[#This Row],[Carga (kg)]]*100/Tabela728[[#This Row],[%1RM CORRESPONDENTE]],"-") -> - | J22: =IFERROR(Tabela728[[#This Row],[CARGA*100/%1RM]]-2.5*(Tabela728[[#This Row],[CARGA*100/%1RM]])*(100-Tabela728[[#This Row],[%1RM CORRESPONDENTE]])/1000,"-") -> - | R22: =IFERROR(VLOOKUP(Tabela72833[[#This Row],[Nº de repetições (entre 1 e 15)]],'[1]Teste Físico'!$T$50:$U$65,2,0),"-") -> - | S22: =IFERROR(Tabela72833[[#This Row],[Carga (kg)]]*100/Tabela72833[[#This Row],[%1RM CORRESPONDENTE]],"-") -> - | T22: =IFERROR(Tabela72833[[#This Row],[CARGA*100/%1RM]]-2.5*(Tabela72833[[#This Row],[CARGA*100/%1RM]])*(100-Tabela72833[[#This Row],[%1RM CORRESPONDENTE]])/1000,"-") -> -
H23: =IFERROR(VLOOKUP(Tabela728[[#This Row],[Nº de repetições (entre 1 e 15)]],'[1]Teste Físico'!$T$50:$U$65,2,0),"-") -> - | I23: =IFERROR(Tabela728[[#This Row],[Carga (kg)]]*100/Tabela728[[#This Row],[%1RM CORRESPONDENTE]],"-") -> - | J23: =IFERROR(Tabela728[[#This Row],[CARGA*100/%1RM]]-2.5*(Tabela728[[#This Row],[CARGA*100/%1RM]])*(100-Tabela728[[#This Row],[%1RM CORRESPONDENTE]])/1000,"-") -> - | R23: =IFERROR(VLOOKUP(Tabela72833[[#This Row],[Nº de repetições (entre 1 e 15)]],'[1]Teste Físico'!$T$50:$U$65,2,0),"-") -> - | S23: =IFERROR(Tabela72833[[#This Row],[Carga (kg)]]*100/Tabela72833[[#This Row],[%1RM CORRESPONDENTE]],"-") -> - | T23: =IFERROR(Tabela72833[[#This Row],[CARGA*100/%1RM]]-2.5*(Tabela72833[[#This Row],[CARGA*100/%1RM]])*(100-Tabela72833[[#This Row],[%1RM CORRESPONDENTE]])/1000,"-") -> -
H24: =IFERROR(VLOOKUP(Tabela728[[#This Row],[Nº de repetições (entre 1 e 15)]],'[1]Teste Físico'!$T$50:$U$65,2,0),"-") -> - | I24: =IFERROR(Tabela728[[#This Row],[Carga (kg)]]*100/Tabela728[[#This Row],[%1RM CORRESPONDENTE]],"-") -> - | J24: =IFERROR(Tabela728[[#This Row],[CARGA*100/%1RM]]-2.5*(Tabela728[[#This Row],[CARGA*100/%1RM]])*(100-Tabela728[[#This Row],[%1RM CORRESPONDENTE]])/1000,"-") -> - | R24: =IFERROR(VLOOKUP(Tabela72833[[#This Row],[Nº de repetições (entre 1 e 15)]],'[1]Teste Físico'!$T$50:$U$65,2,0),"-") -> - | S24: =IFERROR(Tabela72833[[#This Row],[Carga (kg)]]*100/Tabela72833[[#This Row],[%1RM CORRESPONDENTE]],"-") -> - | T24: =IFERROR(Tabela72833[[#This Row],[CARGA*100/%1RM]]-2.5*(Tabela72833[[#This Row],[CARGA*100/%1RM]])*(100-Tabela72833[[#This Row],[%1RM CORRESPONDENTE]])/1000,"-") -> -
H25: =IFERROR(VLOOKUP(Tabela728[[#This Row],[Nº de repetições (entre 1 e 15)]],'[1]Teste Físico'!$T$50:$U$65,2,0),"-") -> - | I25: =IFERROR(Tabela728[[#This Row],[Carga (kg)]]*100/Tabela728[[#This Row],[%1RM CORRESPONDENTE]],"-") -> - | J25: =IFERROR(Tabela728[[#This Row],[CARGA*100/%1RM]]-2.5*(Tabela728[[#This Row],[CARGA*100/%1RM]])*(100-Tabela728[[#This Row],[%1RM CORRESPONDENTE]])/1000,"-") -> - | R25: =IFERROR(VLOOKUP(Tabela72833[[#This Row],[Nº de repetições (entre 1 e 15)]],'[1]Teste Físico'!$T$50:$U$65,2,0),"-") -> - | S25: =IFERROR(Tabela72833[[#This Row],[Carga (kg)]]*100/Tabela72833[[#This Row],[%1RM CORRESPONDENTE]],"-") -> - | T25: =IFERROR(Tabela72833[[#This Row],[CARGA*100/%1RM]]-2.5*(Tabela72833[[#This Row],[CARGA*100/%1RM]])*(100-Tabela72833[[#This Row],[%1RM CORRESPONDENTE]])/1000,"-") -> -
H26: =IFERROR(VLOOKUP(Tabela728[[#This Row],[Nº de repetições (entre 1 e 15)]],'[1]Teste Físico'!$T$50:$U$65,2,0),"-") -> - | I26: =IFERROR(Tabela728[[#This Row],[Carga (kg)]]*100/Tabela728[[#This Row],[%1RM CORRESPONDENTE]],"-") -> - | J26: =IFERROR(Tabela728[[#This Row],[CARGA*100/%1RM]]-2.5*(Tabela728[[#This Row],[CARGA*100/%1RM]])*(100-Tabela728[[#This Row],[%1RM CORRESPONDENTE]])/1000,"-") -> - | R26: =IFERROR(VLOOKUP(Tabela72833[[#This Row],[Nº de repetições (entre 1 e 15)]],'[1]Teste Físico'!$T$50:$U$65,2,0),"-") -> - | S26: =IFERROR(Tabela72833[[#This Row],[Carga (kg)]]*100/Tabela72833[[#This Row],[%1RM CORRESPONDENTE]],"-") -> - | T26: =IFERROR(Tabela72833[[#This Row],[CARGA*100/%1RM]]-2.5*(Tabela72833[[#This Row],[CARGA*100/%1RM]])*(100-Tabela72833[[#This Row],[%1RM CORRESPONDENTE]])/1000,"-") -> -
D43: USO INTERNO
D44: EXERCÍCIOS 1RM | H44: Nº de repetições | I44: % 1RM
D45: Puxada frontal | H45: 1 | I45: 100
D46: Supino reto | H46: 2 | I46: 95
D47: Supino inclinado no smith | H47: 3 | I47: 93
D48: Desenvolvimento máquina | H48: 4 | I48: 90
D49: Supino inclinado | H49: 5 | I49: 87
H50: 6 | I50: 85
D51: Extensora | H51: 7 | I51: 83
D52: Cadeira flexora | H52: 8 | I52: 80
D53: Mesa flexora | H53: 9 | I53: 77
D54: Agachamento livre com a barra | H54: 10 | I54: 75
D55: Leg press 45 | H55: 11 | I55: 70
H56: 12 | I56: 67
H57: 13 | I57: 66
H58: 14 | I58: 66
H59: 15 | I59: 65

Sheet Teste AEROBIO
B2: TESTE FÍSICO
F3: ALUNO: | G3: =Menu!E15 -> Gabriel
AB9: Teste 6 minutos
B13: PARTE AERÓBIA
B14: TESTE COOPER 12 MIN | F14: TESTE INCREMENTAL
B15: Data do teste | C15: Distância percorrida em 12min (m) | D15: VO2 máximo (ml.kg/min) | F15: Data do teste | G15: Velocidade inicial (km/h) | H15: Duração dos estágios (s) | I15: Incremento de velocidade por estágio (km/h) | J15: Velocidade máxima atingida (km/h) | K15: Nº de estágios atingidos | L15: Duração do teste (min) | M15: OBS
D16: =IF(Tabela_Teste_Cooper[[#This Row],[Distância percorrida em 12min (m)]]="","-",(Tabela_Teste_Cooper[[#This Row],[Distância percorrida em 12min (m)]]-504.9)/44.73) -> - | K16: =IFERROR((Tabela_Teste_Incremental[[#This Row],[Velocidade máxima atingida (km/h)]]-Tabela_Teste_Incremental[[#This Row],[Velocidade inicial (km/h)]])/Tabela_Teste_Incremental[[#This Row],[Incremento de velocidade por estágio (km/h)]],"-") -> - | L16: =IFERROR(Tabela_Teste_Incremental[[#This Row],[Nº de estágios atingidos]]*Tabela_Teste_Incremental[[#This Row],[Duração dos estágios (s)]]/60,"-") -> -
D17: =IF(Tabela_Teste_Cooper[[#This Row],[Distância percorrida em 12min (m)]]="","-",(Tabela_Teste_Cooper[[#This Row],[Distância percorrida em 12min (m)]]-504.9)/44.73) -> - | F17: =IF(Tabela_Teste_Cooper[[#This Row],[Data do teste]]="","-",Tabela_Teste_Cooper[[#This Row],[Data do teste]]) -> - | K17: =IFERROR((Tabela_Teste_Incremental[[#This Row],[Velocidade máxima atingida (km/h)]]-Tabela_Teste_Incremental[[#This Row],[Velocidade inicial (km/h)]])/Tabela_Teste_Incremental[[#This Row],[Incremento de velocidade por estágio (km/h)]],"-") -> - | L17: =IFERROR(Tabela_Teste_Incremental[[#This Row],[Nº de estágios atingidos]]*Tabela_Teste_Incremental[[#This Row],[Duração dos estágios (s)]]/60,"-") -> -
D18: =IF(Tabela_Teste_Cooper[[#This Row],[Distância percorrida em 12min (m)]]="","-",(Tabela_Teste_Cooper[[#This Row],[Distância percorrida em 12min (m)]]-504.9)/44.73) -> - | F18: =IF(Tabela_Teste_Cooper[[#This Row],[Data do teste]]="","-",Tabela_Teste_Cooper[[#This Row],[Data do teste]]) -> - | K18: =IFERROR((Tabela_Teste_Incremental[[#This Row],[Velocidade máxima atingida (km/h)]]-Tabela_Teste_Incremental[[#This Row],[Velocidade inicial (km/h)]])/Tabela_Teste_Incremental[[#This Row],[Incremento de velocidade por estágio (km/h)]],"-") -> - | L18: =IFERROR(Tabela_Teste_Incremental[[#This Row],[Nº de estágios atingidos]]*Tabela_Teste_Incremental[[#This Row],[Duração dos estágios (s)]]/60,"-") -> -
D19: =IF(Tabela_Teste_Cooper[[#This Row],[Distância percorrida em 12min (m)]]="","-",(Tabela_Teste_Cooper[[#This Row],[Distância percorrida em 12min (m)]]-504.9)/44.73) -> - | F19: =IF(Tabela_Teste_Cooper[[#This Row],[Data do teste]]="","-",Tabela_Teste_Cooper[[#This Row],[Data do teste]]) -> - | K19: =IFERROR((Tabela_Teste_Incremental[[#This Row],[Velocidade máxima atingida (km/h)]]-Tabela_Teste_Incremental[[#This Row],[Velocidade inicial (km/h)]])/Tabela_Teste_Incremental[[#This Row],[Incremento de velocidade por estágio (km/h)]],"-") -> - | L19: =IFERROR(Tabela_Teste_Incremental[[#This Row],[Nº de estágios atingidos]]*Tabela_Teste_Incremental[[#This Row],[Duração dos estágios (s)]]/60,"-") -> -
D20: =IF(Tabela_Teste_Cooper[[#This Row],[Distância percorrida em 12min (m)]]="","-",(Tabela_Teste_Cooper[[#This Row],[Distância percorrida em 12min (m)]]-504.9)/44.73) -> - | F20: =IF(Tabela_Teste_Cooper[[#This Row],[Data do teste]]="","-",Tabela_Teste_Cooper[[#This Row],[Data do teste]]) -> - | K20: =IFERROR((Tabela_Teste_Incremental[[#This Row],[Velocidade máxima atingida (km/h)]]-Tabela_Teste_Incremental[[#This Row],[Velocidade inicial (km/h)]])/Tabela_Teste_Incremental[[#This Row],[Incremento de velocidade por estágio (km/h)]],"-") -> - | L20: =IFERROR(Tabela_Teste_Incremental[[#This Row],[Nº de estágios atingidos]]*Tabela_Teste_Incremental[[#This Row],[Duração dos estágios (s)]]/60,"-") -> -
D21: =IF(Tabela_Teste_Cooper[[#This Row],[Distância percorrida em 12min (m)]]="","-",(Tabela_Teste_Cooper[[#This Row],[Distância percorrida em 12min (m)]]-504.9)/44.73) -> - | F21: =IF(Tabela_Teste_Cooper[[#This Row],[Data do teste]]="","-",Tabela_Teste_Cooper[[#This Row],[Data do teste]]) -> - | K21: =IFERROR((Tabela_Teste_Incremental[[#This Row],[Velocidade máxima atingida (km/h)]]-Tabela_Teste_Incremental[[#This Row],[Velocidade inicial (km/h)]])/Tabela_Teste_Incremental[[#This Row],[Incremento de velocidade por estágio (km/h)]],"-") -> - | L21: =IFERROR(Tabela_Teste_Incremental[[#This Row],[Nº de estágios atingidos]]*Tabela_Teste_Incremental[[#This Row],[Duração dos estágios (s)]]/60,"-") -> -
D22: =IF(Tabela_Teste_Cooper[[#This Row],[Distância percorrida em 12min (m)]]="","-",(Tabela_Teste_Cooper[[#This Row],[Distância percorrida em 12min (m)]]-504.9)/44.73) -> - | F22: =IF(Tabela_Teste_Cooper[[#This Row],[Data do teste]]="","-",Tabela_Teste_Cooper[[#This Row],[Data do teste]]) -> - | K22: =IFERROR((Tabela_Teste_Incremental[[#This Row],[Velocidade máxima atingida (km/h)]]-Tabela_Teste_Incremental[[#This Row],[Velocidade inicial (km/h)]])/Tabela_Teste_Incremental[[#This Row],[Incremento de velocidade por estágio (km/h)]],"-") -> - | L22: =IFERROR(Tabela_Teste_Incremental[[#This Row],[Nº de estágios atingidos]]*Tabela_Teste_Incremental[[#This Row],[Duração dos estágios (s)]]/60,"-") -> -
D23: =IF(Tabela_Teste_Cooper[[#This Row],[Distância percorrida em 12min (m)]]="","-",(Tabela_Teste_Cooper[[#This Row],[Distância percorrida em 12min (m)]]-504.9)/44.73) -> - | F23: =IF(Tabela_Teste_Cooper[[#This Row],[Data do teste]]="","-",Tabela_Teste_Cooper[[#This Row],[Data do teste]]) -> - | K23: =IFERROR((Tabela_Teste_Incremental[[#This Row],[Velocidade máxima atingida (km/h)]]-Tabela_Teste_Incremental[[#This Row],[Velocidade inicial (km/h)]])/Tabela_Teste_Incremental[[#This Row],[Incremento de velocidade por estágio (km/h)]],"-") -> - | L23: =IFERROR(Tabela_Teste_Incremental[[#This Row],[Nº de estágios atingidos]]*Tabela_Teste_Incremental[[#This Row],[Duração dos estágios (s)]]/60,"-") -> -
D24: =IF(Tabela_Teste_Cooper[[#This Row],[Distância percorrida em 12min (m)]]="","-",(Tabela_Teste_Cooper[[#This Row],[Distância percorrida em 12min (m)]]-504.9)/44.73) -> - | F24: =IF(Tabela_Teste_Cooper[[#This Row],[Data do teste]]="","-",Tabela_Teste_Cooper[[#This Row],[Data do teste]]) -> - | K24: =IFERROR((Tabela_Teste_Incremental[[#This Row],[Velocidade máxima atingida (km/h)]]-Tabela_Teste_Incremental[[#This Row],[Velocidade inicial (km/h)]])/Tabela_Teste_Incremental[[#This Row],[Incremento de velocidade por estágio (km/h)]],"-") -> - | L24: =IFERROR(Tabela_Teste_Incremental[[#This Row],[Nº de estágios atingidos]]*Tabela_Teste_Incremental[[#This Row],[Duração dos estágios (s)]]/60,"-") -> -
D25: =IF(Tabela_Teste_Cooper[[#This Row],[Distância percorrida em 12min (m)]]="","-",(Tabela_Teste_Cooper[[#This Row],[Distância percorrida em 12min (m)]]-504.9)/44.73) -> - | F25: =IF(Tabela_Teste_Cooper[[#This Row],[Data do teste]]="","-",Tabela_Teste_Cooper[[#This Row],[Data do teste]]) -> - | K25: =IFERROR((Tabela_Teste_Incremental[[#This Row],[Velocidade máxima atingida (km/h)]]-Tabela_Teste_Incremental[[#This Row],[Velocidade inicial (km/h)]])/Tabela_Teste_Incremental[[#This Row],[Incremento de velocidade por estágio (km/h)]],"-") -> - | L25: =IFERROR(Tabela_Teste_Incremental[[#This Row],[Nº de estágios atingidos]]*Tabela_Teste_Incremental[[#This Row],[Duração dos estágios (s)]]/60,"-") -> -
D26: =IF(Tabela_Teste_Cooper[[#This Row],[Distância percorrida em 12min (m)]]="","-",(Tabela_Teste_Cooper[[#This Row],[Distância percorrida em 12min (m)]]-504.9)/44.73) -> - | F26: =IF(Tabela_Teste_Cooper[[#This Row],[Data do teste]]="","-",Tabela_Teste_Cooper[[#This Row],[Data do teste]]) -> - | K26: =IFERROR((Tabela_Teste_Incremental[[#This Row],[Velocidade máxima atingida (km/h)]]-Tabela_Teste_Incremental[[#This Row],[Velocidade inicial (km/h)]])/Tabela_Teste_Incremental[[#This Row],[Incremento de velocidade por estágio (km/h)]],"-") -> - | L26: =IFERROR(Tabela_Teste_Incremental[[#This Row],[Nº de estágios atingidos]]*Tabela_Teste_Incremental[[#This Row],[Duração dos estágios (s)]]/60,"-") -> -
D27: =IF(Tabela_Teste_Cooper[[#This Row],[Distância percorrida em 12min (m)]]="","-",(Tabela_Teste_Cooper[[#This Row],[Distância percorrida em 12min (m)]]-504.9)/44.73) -> - | F27: =IF(Tabela_Teste_Cooper[[#This Row],[Data do teste]]="","-",Tabela_Teste_Cooper[[#This Row],[Data do teste]]) -> - | K27: =IFERROR((Tabela_Teste_Incremental[[#This Row],[Velocidade máxima atingida (km/h)]]-Tabela_Teste_Incremental[[#This Row],[Velocidade inicial (km/h)]])/Tabela_Teste_Incremental[[#This Row],[Incremento de velocidade por estágio (km/h)]],"-") -> - | L27: =IFERROR(Tabela_Teste_Incremental[[#This Row],[Nº de estágios atingidos]]*Tabela_Teste_Incremental[[#This Row],[Duração dos estágios (s)]]/60,"-") -> -
D28: =IF(Tabela_Teste_Cooper[[#This Row],[Distância percorrida em 12min (m)]]="","-",(Tabela_Teste_Cooper[[#This Row],[Distância percorrida em 12min (m)]]-504.9)/44.73) -> - | F28: =IF(Tabela_Teste_Cooper[[#This Row],[Data do teste]]="","-",Tabela_Teste_Cooper[[#This Row],[Data do teste]]) -> - | K28: =IFERROR((Tabela_Teste_Incremental[[#This Row],[Velocidade máxima atingida (km/h)]]-Tabela_Teste_Incremental[[#This Row],[Velocidade inicial (km/h)]])/Tabela_Teste_Incremental[[#This Row],[Incremento de velocidade por estágio (km/h)]],"-") -> - | L28: =IFERROR(Tabela_Teste_Incremental[[#This Row],[Nº de estágios atingidos]]*Tabela_Teste_Incremental[[#This Row],[Duração dos estágios (s)]]/60,"-") -> -
D29: =IF(Tabela_Teste_Cooper[[#This Row],[Distância percorrida em 12min (m)]]="","-",(Tabela_Teste_Cooper[[#This Row],[Distância percorrida em 12min (m)]]-504.9)/44.73) -> - | F29: =IF(Tabela_Teste_Cooper[[#This Row],[Data do teste]]="","-",Tabela_Teste_Cooper[[#This Row],[Data do teste]]) -> - | K29: =IFERROR((Tabela_Teste_Incremental[[#This Row],[Velocidade máxima atingida (km/h)]]-Tabela_Teste_Incremental[[#This Row],[Velocidade inicial (km/h)]])/Tabela_Teste_Incremental[[#This Row],[Incremento de velocidade por estágio (km/h)]],"-") -> - | L29: =IFERROR(Tabela_Teste_Incremental[[#This Row],[Nº de estágios atingidos]]*Tabela_Teste_Incremental[[#This Row],[Duração dos estágios (s)]]/60,"-") -> -

Sheet Teste ISOMETRICA
D13: PARTE DE ISOMETRIA | P13: PARTE POTENCIA
D14: Tempo gasto em segundos | P14: DATA:
D15: Data do teste | E15: Prancha frontal >60 seg | F15: Prancha lateral direita >45seg | G15: Prancha lateral esquerda >45seg | H15: Teste de Sorensen >60seg | I15: Cadeirinha Bilateral >60seg | J15: Cadeirinha Unilateral Direita >30seg | K15: Cadeirinha Unilateral Esquerda >30seg | L15: Flexao sem apoio >30seg | M15: Flexao com apoio >45seg | N15: Agachamento com peso (20 a 25% PC) >60 seg | P15: THRUSTER >25REPS 10 A 20% PC
P16: CARGA KG
P17: TEMPO
P18: TAXA | Q18: =Q15/Q17 -> #DIV/0! | R18: =R15/R17 -> #DIV/0! | S18: =S15/S17 -> #DIV/0! | T18: =T15/T17 -> #DIV/0! | U18: =U15/U17 -> #DIV/0! | V18: =V15/V17 -> #DIV/0! | W18: =W15/W17 -> #DIV/0!
P19: ABDOMINAL REMADOR
P20: CARGA KG
P21: TEMPO
P22: TAXA | Q22: =Q19/Q21 -> #DIV/0! | R22: =R19/R21 -> #DIV/0! | S22: =S19/S21 -> #DIV/0! | T22: =T19/T21 -> #DIV/0! | U22: =U19/U21 -> #DIV/0! | V22: =V19/V21 -> #DIV/0! | W22: =W19/W21 -> #DIV/0!
P23: FLEXAO DE BRACO
P24: CARGA KG
P25: TEMPO
P26: TAXA | Q26: =Q23/Q25 -> #DIV/0! | R26: =R23/R25 -> #DIV/0! | S26: =S23/S25 -> #DIV/0! | T26: =T23/T25 -> #DIV/0! | U26: =U23/U25 -> #DIV/0! | V26: =V23/V25 -> #DIV/0! | W26: =W23/W25 -> #DIV/0!

Sheet Avaliação Postural
B2: AVALIAÇÃO POSTURAL
E3: ALUNO: | F3: =Menu!E15 -> Gabriel | J3: Avaliacao 1 | M3: Avaliacao 2 | P3: Avaliacao 3 | S3: Avaliacao 4 | V3: Avaliacao 5 | Y3: Avaliacao 6
J4: Frontal | M4: Frontal | P4: Frontal | S4: Frontal | V4: Frontal | Y4: Frontal
J5: =_xlfn.XLOOKUP(J4,F13:F16,G13:G16) -> #VALUE! | M5: =_xlfn.XLOOKUP(M4,F20:F24,G20:G24) -> #VALUE! | P5: =_xlfn.XLOOKUP(P4,F26:F29,G26:G29) -> #VALUE! | S5: =_xlfn.XLOOKUP(S4,F31:F34,G31:G34) -> #VALUE! | V5: =_xlfn.XLOOKUP(V4,F36:F39,G36:G39) -> #VALUE! | Y5: =_xlfn.XLOOKUP(Y4,F41:F44,G41:G44) -> #VALUE!
E13: Avaliacao 1 | F13: Lateral | G13: #VALUE!
E14: Data: | F14: Lateral | G14: #VALUE!
F15: Frontal | G15: #VALUE!
F16: Tras | G16: #VALUE!
E20: Avaliacao 2 | F20: Lateral
E21: Data: | F21: Lateral
F22: Frontal | G22: #VALUE!
F23: Tras
E26: Avaliacao 3 | F26: Lateral
E27: Data: | F27: Lateral
F28: Frontal | G28: #VALUE!
F29: Tras
E31: Avaliacao 4 | F31: Lateral
E32: Data: | F32: Lateral
F33: Frontal | G33: #VALUE!
F34: Tras
E36: Avaliacao 5 | F36: Lateral
E37: Data: | F37: Lateral
F38: Frontal | G38: #VALUE!
F39: Tras
E41: Avaliacao 6 | F41: Lateral
E42: Data: | F42: Lateral
F43: Frontal | G43: #VALUE!
F44: Tras
C47: VISTA POSTERIOR | J47: VISTA FRONTAL | P47: VISTA LATERAL
C48: PARTE DO CORPO | D48: AVALIAÇÃO ALUNO | E48: NIVEL DO DESVIO | F48: MÚSCULOS ENCURTADOS | G48: MÚSCULOS FRACOS | J48: PARTE DO CORPO | K48: AVALIAÇÃO ALUNO | L48: NIVEL DO DESVIO | M48: MÚSCULOS FRACOS | P48: PARTE DO CORPO | Q48: AVALIAÇÃO ALUNO | R48: NIVEL DO DESVIO | S48: MÚSCULOS ENCURTADOS | T48: MÚSCULOS FRACOS
B49: =C49&D49 -> COLUNANeutra | C49: COLUNA | D49: Neutra | E49: =IFERROR(VLOOKUP($B49,$B$58:$G$76,4,0),"-") -> 0 | F49: =IFERROR(VLOOKUP($B49,$B$58:$G$76,5,0),"-") -> - Músculo 1; - Músculo 2; - Músculo 3; - Músculo 4; - Músculo 5. | G49: =IFERROR(VLOOKUP($B49,$B$58:$G$76,6,0),"-") -> - Músculo 1; - Músculo 2; - Músculo 3; - Músculo 4; - Músculo 5. | I49: =J49&K49 -> CABEÇAInclinada - esquerda | J49: CABEÇA | K49: Inclinada - esquerda | L49: =IFERROR(VLOOKUP($I49,$I$58:$M$76,4,0),"-") -> 0 | M49: =IFERROR(VLOOKUP($I49,$I$58:$M$76,6,0),"-") -> - | O49: =P49&Q49 -> CABEÇA | P49: CABEÇA | R49: =IFERROR(VLOOKUP($O49,$O$58:$T$76,4,0),"-") -> - | S49: =IFERROR(VLOOKUP($O49,$O$58:$T$76,5,0),"-") -> - | T49: =IFERROR(VLOOKUP($O49,$O$58:$T$76,6,0),"-") -> -
B50: =C50&D50 -> OMBROSNivelados | C50: OMBROS | D50: Nivelados | E50: =IFERROR(VLOOKUP($B50,$B$58:$G$76,4,0),"-") -> 0 | F50: =IFERROR(VLOOKUP($B50,$B$58:$G$76,5,0),"-") -> - Músculo 1; - Músculo 2; - Músculo 3; - Músculo 4; - Músculo 5. | G50: =IFERROR(VLOOKUP($B50,$B$58:$G$76,6,0),"-") -> - Músculo 1; - Músculo 2; - Músculo 3; - Músculo 4; - Músculo 5. | I50: =J50&K50 -> OMBROS | J50: OMBROS | L50: =IFERROR(VLOOKUP($I50,$I$58:$M$76,4,0),"-") -> - | M50: =IFERROR(VLOOKUP($I50,$I$58:$M$76,6,0),"-") -> - | O50: =P50&Q50 -> OMBROS | P50: OMBROS | R50: =IFERROR(VLOOKUP($O50,$O$58:$T$76,4,0),"-") -> - | S50: =IFERROR(VLOOKUP($O50,$O$58:$T$76,5,0),"-") -> - | T50: =IFERROR(VLOOKUP($O50,$O$58:$T$76,6,0),"-") -> -
B51: =C51&D51 -> ESCÁPULASNeutras | C51: ESCÁPULAS | D51: Neutras | E51: =IFERROR(VLOOKUP($B51,$B$58:$G$76,4,0),"-") -> 0 | F51: =IFERROR(VLOOKUP($B51,$B$58:$G$76,5,0),"-") -> - Músculo 1; - Músculo 2; - Músculo 3; - Músculo 4; - Músculo 5. | G51: =IFERROR(VLOOKUP($B51,$B$58:$G$76,6,0),"-") -> - Músculo 1; - Músculo 2; - Músculo 3; - Músculo 4; - Músculo 5. | I51: =J51&K51 -> LINHA ALBA | J51: LINHA ALBA | L51: =IFERROR(VLOOKUP($I51,$I$58:$M$76,4,0),"-") -> - | M51: =IFERROR(VLOOKUP($I51,$I$58:$M$76,6,0),"-") -> - | O51: =P51&Q51 -> COLUNA TORÁCICA | P51: COLUNA TORÁCICA | R51: =IFERROR(VLOOKUP($O51,$O$58:$T$76,4,0),"-") -> - | S51: =IFERROR(VLOOKUP($O51,$O$58:$T$76,5,0),"-") -> - | T51: =IFERROR(VLOOKUP($O51,$O$58:$T$76,6,0),"-") -> -
B52: =C51&D52 -> ESCÁPULASAbduzidas | D52: Abduzidas | E52: =IFERROR(VLOOKUP($B52,$B$58:$G$76,4,0),"-") -> 0 | F52: =IFERROR(VLOOKUP($B52,$B$58:$G$76,5,0),"-") -> - Músculo 1; - Músculo 2; - Músculo 3; - Músculo 4; - Músculo 5. | G52: =IFERROR(VLOOKUP($B52,$B$58:$G$76,6,0),"-") -> - Músculo 1; - Músculo 2; - Músculo 3; - Músculo 4; - Músculo 5. | I52: =J52&K52 -> MÃOS | J52: MÃOS | L52: =IFERROR(VLOOKUP($I52,$I$58:$M$76,4,0),"-") -> - | M52: =IFERROR(VLOOKUP($I52,$I$58:$M$76,6,0),"-") -> - | O52: =P52&Q52 -> COLUNA LOMBAR | P52: COLUNA LOMBAR | R52: =IFERROR(VLOOKUP($O52,$O$58:$T$76,4,0),"-") -> - | S52: =IFERROR(VLOOKUP($O52,$O$58:$T$76,5,0),"-") -> - | T52: =IFERROR(VLOOKUP($O52,$O$58:$T$76,6,0),"-") -> -
B53: =C51&D53 -> ESCÁPULAS | E53: =IFERROR(VLOOKUP($B53,$B$58:$G$76,4,0),"-") -> - | F53: =IFERROR(VLOOKUP($B53,$B$58:$G$76,5,0),"-") -> - | G53: =IFERROR(VLOOKUP($B53,$B$58:$G$76,6,0),"-") -> - | I53: =J53&K53 -> PELVE - EIAS | J53: PELVE - EIAS | L53: =IFERROR(VLOOKUP($I53,$I$58:$M$76,4,0),"-") -> - | M53: =IFERROR(VLOOKUP($I53,$I$58:$M$76,6,0),"-") -> - | O53: =P53&Q53 -> PELVE | P53: PELVE | R53: =IFERROR(VLOOKUP($O53,$O$58:$T$76,4,0),"-") -> - | S53: =IFERROR(VLOOKUP($O53,$O$58:$T$76,5,0),"-") -> - | T53: =IFERROR(VLOOKUP($O53,$O$58:$T$76,6,0),"-") -> -
B54: =C54&D54 -> PELVE - EIPS | C54: PELVE - EIPS | E54: =IFERROR(VLOOKUP($B54,$B$58:$G$76,4,0),"-") -> - | F54: =IFERROR(VLOOKUP($B54,$B$58:$G$76,5,0),"-") -> - | G54: =IFERROR(VLOOKUP($B54,$B$58:$G$76,6,0),"-") -> - | I54: =J54&K54 -> JOELHOS | J54: JOELHOS | L54: =IFERROR(VLOOKUP($I54,$I$58:$M$76,4,0),"-") -> - | M54: =IFERROR(VLOOKUP($I54,$I$58:$M$76,6,0),"-") -> - | O54: =P54&Q54 -> JOELHOS | P54: JOELHOS | R54: =IFERROR(VLOOKUP($O54,$O$58:$T$76,4,0),"-") -> - | S54: =IFERROR(VLOOKUP($O54,$O$58:$T$76,5,0),"-") -> - | T54: =IFERROR(VLOOKUP($O54,$O$58:$T$76,6,0),"-") -> -
B55: =C55&D55 -> TORNOZELO | C55: TORNOZELO | E55: =IFERROR(VLOOKUP($B55,$B$58:$G$76,4,0),"-") -> - | F55: =IFERROR(VLOOKUP($B55,$B$58:$G$76,5,0),"-") -> - | G55: =IFERROR(VLOOKUP($B55,$B$58:$G$76,6,0),"-") -> -
C57: USO INTERNO
C58: PARTE DO CORPO | D58: AVALIAÇÃO ALUNO | E58: LINK FOTO | F58: MÚSCULOS ENCURTADOS | G58: MÚSCULOS FRACOS | J58: PARTE DO CORPO | K58: AVALIAÇÃO ALUNO | L58: LINK FOTO | M58: MÚSCULOS FRACOS | P58: PARTE DO CORPO | Q58: AVALIAÇÃO ALUNO | R58: LINK FOTO | S58: MÚSCULOS ENCURTADOS | T58: MÚSCULOS FRACOS
B59: =C59&D59 -> COLUNANeutra | C59: COLUNA | D59: Neutra | F59: - Músculo 1; - Músculo 2; - Músculo 3; - Músculo 4; - Músculo 5. | G59: - Músculo 1; - Músculo 2; - Músculo 3; - Músculo 4; - Músculo 5. | I59: =J59&K59 -> CABEÇANeutra | J59: CABEÇA | K59: Neutra | M59: - Músculo 1; - Músculo 2; - Músculo 3; - Músculo 4; - Músculo 5. | O59: =P59&Q59 -> CABEÇANeutra | P59: CABEÇA | Q59: Neutra | S59: - Músculo 1; - Músculo 2; - Músculo 3; - Músculo 4; - Músculo 5. | T59: - Músculo 1; - Músculo 2; - Músculo 3; - Músculo 4; - Músculo 5.
...

Sheet Avaliacao Fotos Antes e Depois
B2: AVALIAÇÃO EVOLUTIVA
E3: ALUNO: | F3: =Menu!E15 -> Gabriel | J3: Avaliacao 1 | M3: Avaliacao 2 | P3: Avaliacao 6 | S3: Avaliacao 4 | V3: Avaliacao 5 | Y3: Avaliacao 6
J4: Lateral | M4: Lateral | P4: Frontal | S4: Frontal | V4: Frontal | Y4: Frontal
J5: =_xlfn.XLOOKUP(J4,F13:F16,G13:G16) -> #VALUE! | M5: =_xlfn.XLOOKUP(M4,F20:F24,G20:G24) -> 0 | P5: =_xlfn.XLOOKUP(P4,F26:F29,G26:G29) -> #VALUE! | S5: =_xlfn.XLOOKUP(S4,F31:F34,G31:G34) -> #VALUE! | V5: =_xlfn.XLOOKUP(V4,F36:F39,G36:G39) -> #VALUE! | Y5: =_xlfn.XLOOKUP(Y4,F41:F44,G41:G44) -> #VALUE!
E13: Avaliacao 1 | F13: Lateral | G13: #VALUE!
E14: Data: | F14: Lateral | G14: #VALUE!
F15: Frontal | G15: #VALUE!
F16: Tras | G16: #VALUE!
E20: Avaliacao 2 | F20: Lateral
E21: Data: | F21: Lateral
F22: Frontal | G22: #VALUE!
F23: Tras
E26: Avaliacao 3 | F26: Lateral
E27: Data: | F27: Lateral
F28: Frontal | G28: #VALUE!
F29: Tras
E31: Avaliacao 4 | F31: Lateral
E32: Data: | F32: Lateral
F33: Frontal | G33: #VALUE!
F34: Tras
E36: Avaliacao 5 | F36: Lateral
E37: Data: | F37: Lateral
F38: Frontal | G38: #VALUE!
F39: Tras
E41: Avaliacao 6 | F41: Lateral
E42: Data: | F42: Lateral
F43: Frontal | G43: #VALUE!
F44: Tras

Sheet Planilha2
B2: AVALIACAO | C2: Avaliacao 2
